<?xml version="1.0" encoding="UTF-8"?>
<!-- Generated by org.testng.reporters.JUnitReportReporter -->
<testsuite hostname="Swetha" failures="3" tests="6" name="test.DemoTest" time="287.403" errors="1" timestamp="2023-04-05T02:08:19 IST" skipped="0">
  <testcase classname="test.DemoTest" name="createUse" time="44.596"/>
  <system-out/>
  <testcase classname="test.DemoTest" name="createUse" time="52.394">
    <failure message="Added User not found in List Of Users expected [Raj, Ram] but found [Priya, Vishnu]" type="java.lang.AssertionError">
      <![CDATA[java.lang.AssertionError: Added User not found in List Of Users expected [Raj, Ram] but found [Priya, Vishnu]
at org.testng.Assert.fail(Assert.java:110)
at org.testng.Assert.failNotEquals(Assert.java:1577)
at org.testng.Assert.assertEqualsImpl(Assert.java:149)
at org.testng.Assert.assertEquals(Assert.java:131)
at org.testng.Assert.assertEquals(Assert.java:655)
at pageObjects.Users.verifyAddedUserInListOfUsers(Users.java:37)
at test.DemoTest.createUse(DemoTest.java:52)
at java.base/jdk.internal.reflect.DirectMethodHandleAccessor.invoke(DirectMethodHandleAccessor.java:104)
at java.base/java.lang.reflect.Method.invoke(Method.java:578)
at org.testng.internal.invokers.MethodInvocationHelper.invokeMethod(MethodInvocationHelper.java:139)
at org.testng.internal.invokers.TestInvoker.invokeMethod(TestInvoker.java:677)
at org.testng.internal.invokers.TestInvoker.invokeTestMethod(TestInvoker.java:221)
at org.testng.internal.invokers.MethodRunner.runInSequence(MethodRunner.java:50)
at org.testng.internal.invokers.TestInvoker$MethodInvocationAgent.invoke(TestInvoker.java:969)
at org.testng.internal.invokers.TestInvoker.invokeTestMethods(TestInvoker.java:194)
at org.testng.internal.invokers.TestMethodWorker.invokeTestMethods(TestMethodWorker.java:148)
at org.testng.internal.invokers.TestMethodWorker.run(TestMethodWorker.java:128)
at java.base/java.util.concurrent.ThreadPoolExecutor.runWorker(ThreadPoolExecutor.java:1144)
at java.base/java.util.concurrent.ThreadPoolExecutor$Worker.run(ThreadPoolExecutor.java:642)
at java.base/java.lang.Thread.run(Thread.java:1589)
]]>
    </failure>
  </testcase> <!-- createUse -->
  <system-out/>
  <testcase classname="test.DemoTest" name="createUser" time="46.456"/>
  <system-out/>
  <testcase classname="test.DemoTest" name="createUser" time="48.349">
    <failure message="Added User not found in List Of Users expected [Raj, Ram] but found [Priya, Vishnu]" type="java.lang.AssertionError">
      <![CDATA[java.lang.AssertionError: Added User not found in List Of Users expected [Raj, Ram] but found [Priya, Vishnu]
at org.testng.Assert.fail(Assert.java:110)
at org.testng.Assert.failNotEquals(Assert.java:1577)
at org.testng.Assert.assertEqualsImpl(Assert.java:149)
at org.testng.Assert.assertEquals(Assert.java:131)
at org.testng.Assert.assertEquals(Assert.java:655)
at pageObjects.Users.verifyAddedUserInListOfUsers(Users.java:37)
at test.DemoTest.createUser(DemoTest.java:32)
at java.base/jdk.internal.reflect.DirectMethodHandleAccessor.invoke(DirectMethodHandleAccessor.java:104)
at java.base/java.lang.reflect.Method.invoke(Method.java:578)
at org.testng.internal.invokers.MethodInvocationHelper.invokeMethod(MethodInvocationHelper.java:139)
at org.testng.internal.invokers.TestInvoker.invokeMethod(TestInvoker.java:677)
at org.testng.internal.invokers.TestInvoker.invokeTestMethod(TestInvoker.java:221)
at org.testng.internal.invokers.MethodRunner.runInSequence(MethodRunner.java:50)
at org.testng.internal.invokers.TestInvoker$MethodInvocationAgent.invoke(TestInvoker.java:969)
at org.testng.internal.invokers.TestInvoker.invokeTestMethods(TestInvoker.java:194)
at org.testng.internal.invokers.TestMethodWorker.invokeTestMethods(TestMethodWorker.java:148)
at org.testng.internal.invokers.TestMethodWorker.run(TestMethodWorker.java:128)
at java.base/java.util.concurrent.ThreadPoolExecutor.runWorker(ThreadPoolExecutor.java:1144)
at java.base/java.util.concurrent.ThreadPoolExecutor$Worker.run(ThreadPoolExecutor.java:642)
at java.base/java.lang.Thread.run(Thread.java:1589)
]]>
    </failure>
  </testcase> <!-- createUser -->
  <system-out/>
  <testcase classname="test.DemoTest" name="createUser" time="49.466">
    <failure message="Added User not found in List Of Users expected [Raj, Ram] but found [Kapoor, Rishi]" type="java.lang.AssertionError">
      <![CDATA[java.lang.AssertionError: Added User not found in List Of Users expected [Raj, Ram] but found [Kapoor, Rishi]
at org.testng.Assert.fail(Assert.java:110)
at org.testng.Assert.failNotEquals(Assert.java:1577)
at org.testng.Assert.assertEqualsImpl(Assert.java:149)
at org.testng.Assert.assertEquals(Assert.java:131)
at org.testng.Assert.assertEquals(Assert.java:655)
at pageObjects.Users.verifyAddedUserInListOfUsers(Users.java:37)
at test.DemoTest.createUser(DemoTest.java:32)
at java.base/jdk.internal.reflect.DirectMethodHandleAccessor.invoke(DirectMethodHandleAccessor.java:104)
at java.base/java.lang.reflect.Method.invoke(Method.java:578)
at org.testng.internal.invokers.MethodInvocationHelper.invokeMethod(MethodInvocationHelper.java:139)
at org.testng.internal.invokers.TestInvoker.invokeMethod(TestInvoker.java:677)
at org.testng.internal.invokers.TestInvoker.invokeTestMethod(TestInvoker.java:221)
at org.testng.internal.invokers.MethodRunner.runInSequence(MethodRunner.java:50)
at org.testng.internal.invokers.TestInvoker$MethodInvocationAgent.invoke(TestInvoker.java:969)
at org.testng.internal.invokers.TestInvoker.invokeTestMethods(TestInvoker.java:194)
at org.testng.internal.invokers.TestMethodWorker.invokeTestMethods(TestMethodWorker.java:148)
at org.testng.internal.invokers.TestMethodWorker.run(TestMethodWorker.java:128)
at java.base/java.util.concurrent.ThreadPoolExecutor.runWorker(ThreadPoolExecutor.java:1144)
at java.base/java.util.concurrent.ThreadPoolExecutor$Worker.run(ThreadPoolExecutor.java:642)
at java.base/java.lang.Thread.run(Thread.java:1589)
]]>
    </failure>
  </testcase> <!-- createUser -->
  <system-out/>
  <testcase classname="test.DemoTest" name="createUse" time="46.142">
    <error message="unexpected alert open: {Alert text : Unexpected error occurred.
Please contact actiTIME support team.

 Error details:

JSON-RPC error 490
exception: com.mysql.jdbc.exceptions.jdbc4.MySQLIntegrityConstraintViolationException
message: Duplicate entry &#039;rishi1&#039; for key &#039;username&#039;
More info is available in the browser console.}
  (Session info: chrome=111.0.5563.147): Unexpected error occurred.
Please contact actiTIME support team.

 Error details:

JSON-RPC error 490
exception: com.mysql.jdbc.exceptions.jdbc4.MySQLIntegrityConstraintViolationException
message: Duplicate entry &#039;rishi1&#039; for key &#039;username&#039;
More info is available in the browser console.
Build info: version: &#039;4.8.3&#039;, revision: &#039;e5e76298c3&#039;
System info: os.name: &#039;Windows 11&#039;, os.arch: &#039;amd64&#039;, os.version: &#039;10.0&#039;, java.version: &#039;19.0.2&#039;
Driver info: org.openqa.selenium.chrome.ChromeDriver
Command: [735a7d7d6a384d52d4be1d45a491770b, findElement {using=id, value=logo_aT}]
Capabilities {acceptInsecureCerts: false, browserName: chrome, browserVersion: 111.0.5563.147, chrome: {chromedriverVersion: 111.0.5563.64 (c710e93d5b63..., userDataDir: C:\Users\sweth\AppData\Loca...}, goog:chromeOptions: {debuggerAddress: localhost:49297}, networkConnectionEnabled: false, pageLoadStrategy: normal, platformName: WINDOWS, proxy: Proxy(), se:cdp: ws://localhost:49297/devtoo..., se:cdpVersion: 111.0.5563.147, setWindowRect: true, strictFileInteractability: false, timeouts: {implicit: 0, pageLoad: 300000, script: 30000}, unhandledPromptBehavior: dismiss and notify, webauthn:extension:credBlob: true, webauthn:extension:largeBlob: true, webauthn:extension:minPinLength: true, webauthn:extension:prf: true, webauthn:virtualAuthenticators: true}
Session ID: 735a7d7d6a384d52d4be1d45a491770b" type="org.openqa.selenium.UnhandledAlertException">
      <![CDATA[org.openqa.selenium.UnhandledAlertException: unexpected alert open: {Alert text : Unexpected error occurred.
Please contact actiTIME support team.

 Error details:

JSON-RPC error 490
exception: com.mysql.jdbc.exceptions.jdbc4.MySQLIntegrityConstraintViolationException
message: Duplicate entry 'rishi1' for key 'username'
More info is available in the browser console.}
  (Session info: chrome=111.0.5563.147): Unexpected error occurred.
Please contact actiTIME support team.

 Error details:

JSON-RPC error 490
exception: com.mysql.jdbc.exceptions.jdbc4.MySQLIntegrityConstraintViolationException
message: Duplicate entry 'rishi1' for key 'username'
More info is available in the browser console.
Build info: version: '4.8.3', revision: 'e5e76298c3'
System info: os.name: 'Windows 11', os.arch: 'amd64', os.version: '10.0', java.version: '19.0.2'
Driver info: org.openqa.selenium.chrome.ChromeDriver
Command: [735a7d7d6a384d52d4be1d45a491770b, findElement {using=id, value=logo_aT}]
Capabilities {acceptInsecureCerts: false, browserName: chrome, browserVersion: 111.0.5563.147, chrome: {chromedriverVersion: 111.0.5563.64 (c710e93d5b63..., userDataDir: C:\Users\sweth\AppData\Loca...}, goog:chromeOptions: {debuggerAddress: localhost:49297}, networkConnectionEnabled: false, pageLoadStrategy: normal, platformName: WINDOWS, proxy: Proxy(), se:cdp: ws://localhost:49297/devtoo..., se:cdpVersion: 111.0.5563.147, setWindowRect: true, strictFileInteractability: false, timeouts: {implicit: 0, pageLoad: 300000, script: 30000}, unhandledPromptBehavior: dismiss and notify, webauthn:extension:credBlob: true, webauthn:extension:largeBlob: true, webauthn:extension:minPinLength: true, webauthn:extension:prf: true, webauthn:virtualAuthenticators: true}
Session ID: 735a7d7d6a384d52d4be1d45a491770b
at org.openqa.selenium.remote.codec.w3c.W3CHttpResponseCodec.decode(W3CHttpResponseCodec.java:131)
at org.openqa.selenium.remote.codec.w3c.W3CHttpResponseCodec.decode(W3CHttpResponseCodec.java:53)
at org.openqa.selenium.remote.HttpCommandExecutor.execute(HttpCommandExecutor.java:193)
at org.openqa.selenium.remote.service.DriverCommandExecutor.invokeExecute(DriverCommandExecutor.java:183)
at org.openqa.selenium.remote.service.DriverCommandExecutor.execute(DriverCommandExecutor.java:158)
at org.openqa.selenium.remote.RemoteWebDriver.execute(RemoteWebDriver.java:543)
at org.openqa.selenium.remote.ElementLocation$ElementFinder$2.findElement(ElementLocation.java:162)
at org.openqa.selenium.remote.ElementLocation.findElement(ElementLocation.java:60)
at org.openqa.selenium.remote.RemoteWebDriver.findElement(RemoteWebDriver.java:352)
at org.openqa.selenium.remote.RemoteWebDriver.findElement(RemoteWebDriver.java:344)
at pageObjects.Home.checkHomePageNavigation(Home.java:29)
at test.DemoTest.createUse(DemoTest.java:50)
at java.base/jdk.internal.reflect.DirectMethodHandleAccessor.invoke(DirectMethodHandleAccessor.java:104)
at java.base/java.lang.reflect.Method.invoke(Method.java:578)
at org.testng.internal.invokers.MethodInvocationHelper.invokeMethod(MethodInvocationHelper.java:139)
at org.testng.internal.invokers.TestInvoker.invokeMethod(TestInvoker.java:677)
at org.testng.internal.invokers.TestInvoker.invokeTestMethod(TestInvoker.java:221)
at org.testng.internal.invokers.MethodRunner.runInSequence(MethodRunner.java:50)
at org.testng.internal.invokers.TestInvoker$MethodInvocationAgent.invoke(TestInvoker.java:969)
at org.testng.internal.invokers.TestInvoker.invokeTestMethods(TestInvoker.java:194)
at org.testng.internal.invokers.TestMethodWorker.invokeTestMethods(TestMethodWorker.java:148)
at org.testng.internal.invokers.TestMethodWorker.run(TestMethodWorker.java:128)
at java.base/java.util.concurrent.ThreadPoolExecutor.runWorker(ThreadPoolExecutor.java:1144)
at java.base/java.util.concurrent.ThreadPoolExecutor$Worker.run(ThreadPoolExecutor.java:642)
at java.base/java.lang.Thread.run(Thread.java:1589)
]]>
    </error>
  </testcase> <!-- createUse -->
  <system-out/>
</testsuite> <!-- test.DemoTest -->
